Traceback (most recent call last):
  File "/home/runner/work/geog-312/geog-312/.venv/lib/python3.12/site-packages/jupyter_cache/executors/utils.py", line 58, in single_nb_execution
    executenb(
  File "/home/runner/work/geog-312/geog-312/.venv/lib/python3.12/site-packages/nbclient/client.py", line 1314, in execute
    return NotebookClient(nb=nb, resources=resources, km=km, **kwargs).execute()
           ^^^^^^^^^^^^^^^^^^^^^^^^^^^^^^^^^^^^^^^^^^^^^^^^^^^^^^^^^^^^^^^^^^^^^
  File "/home/runner/work/geog-312/geog-312/.venv/lib/python3.12/site-packages/jupyter_core/utils/__init__.py", line 165, in wrapped
    return loop.run_until_complete(inner)
           ^^^^^^^^^^^^^^^^^^^^^^^^^^^^^^
  File "/home/runner/.local/share/uv/python/cpython-3.12.6-linux-x86_64-gnu/lib/python3.12/asyncio/base_events.py", line 687, in run_until_complete
    return future.result()
           ^^^^^^^^^^^^^^^
  File "/home/runner/work/geog-312/geog-312/.venv/lib/python3.12/site-packages/nbclient/client.py", line 709, in async_execute
    await self.async_execute_cell(
  File "/home/runner/work/geog-312/geog-312/.venv/lib/python3.12/site-packages/nbclient/client.py", line 1062, in async_execute_cell
    await self._check_raise_for_error(cell, cell_index, exec_reply)
  File "/home/runner/work/geog-312/geog-312/.venv/lib/python3.12/site-packages/nbclient/client.py", line 918, in _check_raise_for_error
    raise CellExecutionError.from_cell_and_msg(cell, exec_reply_content)
nbclient.exceptions.CellExecutionError: An error occurred while executing the following cell:
------------------
gdf = leafmap.get_wbd(geometry, digit=10, return_geometry=True)
gdf.explore()
------------------


[0;31m---------------------------------------------------------------------------[0m
[0;31mAttributeError[0m                            Traceback (most recent call last)
Cell [0;32mIn[8], line 2[0m
[1;32m      1[0m gdf [38;5;241m=[39m leafmap[38;5;241m.[39mget_wbd(geometry, digit[38;5;241m=[39m[38;5;241m10[39m, return_geometry[38;5;241m=[39m[38;5;28;01mTrue[39;00m)
[0;32m----> 2[0m [43mgdf[49m[38;5;241;43m.[39;49m[43mexplore[49m()

[0;31mAttributeError[0m: 'dict' object has no attribute 'explore'

